Traceback (most recent call last):
  File "/home/alejo/.local/lib/python3.10/site-packages/jupyter_cache/executors/utils.py", line 58, in single_nb_execution
    executenb(
  File "/home/alejo/.local/lib/python3.10/site-packages/nbclient/client.py", line 1305, in execute
    return NotebookClient(nb=nb, resources=resources, km=km, **kwargs).execute()
  File "/home/alejo/.local/lib/python3.10/site-packages/jupyter_core/utils/__init__.py", line 173, in wrapped
    return loop.run_until_complete(inner)
  File "/usr/lib/python3.10/asyncio/base_events.py", line 649, in run_until_complete
    return future.result()
  File "/home/alejo/.local/lib/python3.10/site-packages/nbclient/client.py", line 705, in async_execute
    await self.async_execute_cell(
  File "/home/alejo/.local/lib/python3.10/site-packages/nbclient/client.py", line 1058, in async_execute_cell
    await self._check_raise_for_error(cell, cell_index, exec_reply)
  File "/home/alejo/.local/lib/python3.10/site-packages/nbclient/client.py", line 914, in _check_raise_for_error
    raise CellExecutionError.from_cell_and_msg(cell, exec_reply_content)
nbclient.exceptions.CellExecutionError: An error occurred while executing the following cell:
------------------
# read .rds file
import pyreadr
df = pyreadr.read_r('./data/ENDI/BDD_ENDI_R1_rds/rds/BDD_ENDI_R1_f1_personas.rds')

------------------


[0;31m---------------------------------------------------------------------------[0m
[0;31mModuleNotFoundError[0m                       Traceback (most recent call last)
Cell [0;32mIn[4], line 2[0m
[1;32m      1[0m [38;5;66;03m# read .rds file[39;00m
[0;32m----> 2[0m [38;5;28;01mimport[39;00m [38;5;21;01mpyreadr[39;00m
[1;32m      3[0m df [38;5;241m=[39m pyreadr[38;5;241m.[39mread_r([38;5;124m'[39m[38;5;124m./data/ENDI/BDD_ENDI_R1_rds/rds/BDD_ENDI_R1_f1_personas.rds[39m[38;5;124m'[39m)

[0;31mModuleNotFoundError[0m: No module named 'pyreadr'

